Workbook

Sheet Діаграми
A2: JIT та Native AOT: результати низького навантаження
A3: Рівень low. .NET 9.0.20. Усі діаграми побудовані за новою серією з 8 запусків.
A22: Як працює прогрів
A23: 32 виклики — це мінімум. Цикл завершується, коли одночасно виконано не менше 32 викликів і минуло не менше 500 мс.
A24: Коли один виклик швидкий, за цей час їх можуть бути тисячі. У задачі 1: JIT — 8715 викликів, Native AOT — 9957.
A25: 1717 викликів було в попередньому прикладі. Кількість залежить від швидкості викликів і може змінюватися між запусками.
A26: Після циклу є додаткова пауза 150 мс. Вона включена у загальний час на діаграмі, тому задачі 1–3 мають близько 650–665 мс.
A27: У задачі 4 один виклик містить асинхронні очікування. Для 32 викликів знадобилося понад 5 секунд. 500 мс — нижня межа.
A28: Native AOT проходить той самий підготовчий етап. Показаний час — тривалість Warmup(), а не точний час роботи JIT-компілятора.
A29: Прогрів виконується на малих даних. Три прогріті повтори після нього виконують повний тест обраного рівня low.
A30: У наданому журналі є сумарний час і кількість викликів прогріву. Часу кожного з них немає, тому графік окремих викликів не побудовано.
A31: На діаграмі прогріву підписи округлено до цілих мілісекунд. Точні значення збережено на аркуші «Дані».
... A51: Медіана — середнє за порядком із трьох значень, відсортованих за величиною. Перший виклик і етап прогріву в неї не входять.
A53: Задача / операція | B53: JIT, мс | C53: AOT, мс | D53: Δ часу | E53: Перший JIT, мс | F53: Перший AOT, мс | J53: Що показала ця серія
A54: 1. Матриці | B54: =Дані!E20 -> 27.99 | C54: =Дані!E21 -> 25.37 | D54: =C54/B54-1 -> -0.093604859 | E54: =Дані!D20 -> 29.34 | F54: =Дані!D21 -> 25.6 | J54: AOT має менші медіани у задачах 1–3.
A55: 2. GC | B55: =Дані!E22 -> 2.04 | C55: =Дані!E23 -> 1.74 | D55: =C55/B55-1 -> -0.14705882 | E55: =Дані!D22 -> 7.1 | F55: =Дані!D23 -> 4.85 | J55: Для Async різниця становить лише близько 0,42%.
A56: 3. Запис | B56: =Дані!E24 -> 2.98 | C56: =Дані!E26 -> 1.31 | D56: =C56/B56-1 -> -0.56040268 | E56: =Дані!D24 -> 51.43 | F56: =Дані!D26 -> 1.69 | J56: З трьох повторів не можна довести сталу перевагу.
A57: 3. Читання | B57: =Дані!E25 -> 5.15 | C57: =Дані!E27 -> 2.11 | D57: =C57/B57-1 -> -0.59029126 | E57: =Дані!D25 -> 13.78 | F57: =Дані!D27 -> 2.22 | J57: У Task3 відрізняється і спосіб роботи з JSON:
A58: 4. Async | B58: =Дані!E28 -> 1579.94 | C58: =Дані!E29 -> 1586.63 | D58: =C58/B58-1 -> 0.004234338 | E58: =Дані!D28 -> 1575.75 | F58: =Дані!D29 -> 1596.92 | J58: JIT використовує Reflection, AOT — Source Generator.
A78: Як читати показники пам’яті та розміру
A79: Пік RAM — найбільший робочий набір за життя процесу. Для запису й читання JSON наведено один спільний пік сеансу.
A80: «Виділено, MiB» — сума керованих виділень за конкретний виміряний виклик. Це інший показник, ніж RAM процесу.
A81: У задачі 1 «Виділено» дорівнює 0,00 MiB: масиви створені перед вимірюванням множення, хоча вони займають RAM.
A82: Розмір EXE — розмір запущеного готового файлу на диску. 1 MiB = 1 048 576 байт. Точні байти є на аркуші «Дані».
A83: У цій серії AOT має менший холодний старт, менший EXE і нижчий пік RAM у всіх чотирьох задачах.
A84: Висновки стосуються навантаження low на цьому комп’ютері. Результатів medium та high у цій серії немає.
A87: Умови навантаження low
A88: Задача 1: множення матриць 500 × 500, SIMD — 8 float у векторі. Прогрів: матриці 64 × 64.
A89: Задача 2: 100 000 об’єктів, LOH не використовується. Прогрів: 4000 об’єктів за один виклик.
A90: Задача 3: 1000 об’єктів UserSession, JSON — 0,48 MiB. Прогрів: запис і читання 32 об’єктів за один виклик.
A91: Задача 4: 1000 асинхронних операцій, конкурентність 10. Прогрів: 100 операцій із конкурентністю 10 за один виклик.
A92: Конкурентність — кількість одночасно активних обробників. Фактичну кількість потоків ThreadPool наведено в даних.

Sheet Дані
A1: Джерело: консольні результати користувача, отримані 13.10.2026. Рівень low, .NET 9.0.20.
A2: Порожні клітинки: показник не наведено для цієї задачі. Число 0 — виміряне нульове значення.
A4: Показники сеансів
A5: Задача | B5: Режим | C5: Холодний старт, мс | D5: Прогрів із паузою, мс | E5: Викликів прогріву | F5: EXE, байт | G5: EXE, MiB у консолі | H5: Пік RAM, MiB | I5: JSON, MiB
A6: 1 | B6: JIT | C6: 31.13 | D6: 664.95 | E6: 8715 | F6: 70902530 | G6: 67.62 | H6: 24.49
A7: 1 | B7: Native AOT | C7: 6.98 | D7: 663.04 | E7: 9957 | F7: 1904640 | G7: 1.82 | H7: 11.84
A8: 2 | B8: JIT | C8: 31.53 | D8: 654.03 | E8: 7160 | F8: 70902530 | G8: 67.62 | H8: 31.26
A9: 2 | B9: Native AOT | C9: 6.76 | D9: 655.63 | E9: 7608 | F9: 1906688 | G9: 1.82 | H9: 18.49
A10: 3 | B10: JIT | C10: 32.03 | D10: 665.29 | E10: 1441 | F10: 70923010 | G10: 67.64 | H10: 39.85 | I10: 0.48
A11: 3 | B11: Native AOT | C11: 7 | D11: 658.52 | E11: 3185 | F11: 3006976 | G11: 2.87 | H11: 14.39 | I11: 0.48
A12: 4 | B12: JIT | C12: 30.42 | D12: 5249.71 | E12: 32 | F12: 70906626 | G12: 67.62 | H12: 27.71
A13: 4 | B13: Native AOT | C13: 7.04 | D13: 5257.4 | E13: 32 | F13: 1987072 | G13: 1.9 | H13: 10.41
A15: Усі перевірки результатів у журналі: OK. Задача 1: 500 × 500, SIMD — 8 float. Задача 2: 100 000 об’єктів, без LOH.
A16: Задача 3: 1000 UserSession, JIT + Reflection та AOT + Source Generator. Задача 4: 1000 операцій, конкурентність 10.
A18: Розрахунки за виміряними викликами
A19: Задача | B19: Режим | C19: Операція | D19: Перший виклик, мс | E19: Медіана 1–3, мс | F19: Мінімум 1–3, мс | G19: Максимум 1–3, мс | H19: Медіана виділено, MiB | I19: Медіана пауз GC, мс
A20: 1 | B20: JIT | C20: Матриці | D20: =F34 -> 29.34 | E20: =MEDIAN(F35,F36,F37) -> 27.99 | F20: =MIN(F35,F36,F37) -> 27.86 | G20: =MAX(F35,F36,F37) -> 28.5 | H20: =MEDIAN(G35,G36,G37) -> 0
A21: 1 | B21: Native AOT | C21: Матриці | D21: =F38 -> 25.6 | E21: =MEDIAN(F39,F40,F41) -> 25.37 | F21: =MIN(F39,F40,F41) -> 25.3 | G21: =MAX(F39,F40,F41) -> 25.79 | H21: =MEDIAN(G39,G40,G41) -> 0
A22: 2 | B22: JIT | C22: Об’єкти та GC | D22: =F42 -> 7.1 | E22: =MEDIAN(F43,F44,F45) -> 2.04 | F22: =MIN(F43,F44,F45) -> 1.99 | G22: =MAX(F43,F44,F45) -> 2.19 | H22: =MEDIAN(G43,G44,G45) -> 8.39 | I22: =MEDIAN(L43,L44,L45) -> 0.68
A23: 2 | B23: Native AOT | C23: Об’єкти та GC | D23: =F46 -> 4.85 | E23: =MEDIAN(F47,F48,F49) -> 1.74 | F23: =MIN(F47,F48,F49) -> 1.68 | G23: =MAX(F47,F48,F49) -> 2.05 | H23: =MEDIAN(G47,G48,G49) -> 8.39 | I23: =MEDIAN(L47,L48,L49) -> 0.48
A24: 3 | B24: JIT | C24: Запис JSON | D24: =F50 -> 51.43 | E24: =MEDIAN(F52,F54,F56) -> 2.98 | F24: =MIN(F52,F54,F56) -> 2.75 | G24: =MAX(F52,F54,F56) -> 3.14 | H24: =MEDIAN(G52,G54,G56) -> 1
A25: 3 | B25: JIT | C25: Читання JSON | D25: =F51 -> 13.78 | E25: =MEDIAN(F53,F55,F57) -> 5.15 | F25: =MIN(F53,F55,F57) -> 4.95 | G25: =MAX(F53,F55,F57) -> 5.65 | H25: =MEDIAN(G53,G55,G57) -> 0.99
A26: 3 | B26: Native AOT | C26: Запис JSON | D26: =F58 -> 1.69 | E26: =MEDIAN(F60,F62,F64) -> 1.31 | F26: =MIN(F60,F62,F64) -> 0.94 | G26: =MAX(F60,F62,F64) -> 1.73 | H26: =MEDIAN(G60,G62,G64) -> 1
A27: 3 | B27: Native AOT | C27: Читання JSON | D27: =F59 -> 2.22 | E27: =MEDIAN(F61,F63,F65) -> 2.11 | F27: =MIN(F61,F63,F65) -> 2.01 | G27: =MAX(F61,F63,F65) -> 2.15 | H27: =MEDIAN(G61,G63,G65) -> 0.99
A28: 4 | B28: JIT | C28: Async | D28: =F66 -> 1575.75 | E28: =MEDIAN(F67,F68,F69) -> 1579.94 | F28: =MIN(F67,F68,F69) -> 1574.91 | G28: =MAX(F67,F68,F69) -> 1585.98 | H28: =MEDIAN(G67,G68,G69) -> 0.26
A29: 4 | B29: Native AOT | C29: Async | D29: =F70 -> 1596.92 | E29: =MEDIAN(F71,F72,F73) -> 1586.63 | F29: =MIN(F71,F72,F73) -> 1581.39 | G29: =MAX(F71,F72,F73) -> 1590.06 | H29: =MEDIAN(G71,G72,G73) -> 0.26
A32: Вихідні вимірювання. Виклик 0 — перший, виклики 1–3 — прогріті повтори повного тесту.
A33: Сеанс | B33: Задача | C33: Режим | D33: Операція | E33: Виклик | F33: Час, мс | G33: Виділено, MiB | H33: RAM після, MiB | I33: GC Gen0 | J33: GC Gen1 | K33: GC Gen2 | L33: Пауза GC, мс | M33: ThreadPool на початку | N33: Пік ThreadPool | O33: До піку пулу, мс
A34: 1 | B34: 1 | C34: JIT | D34: Матриці | E34: 0 | F34: 29.34 | G34: 0 | H34: 24.29
A35: 1 | B35: 1 | C35: JIT | D35: Матриці | E35: 1 | F35: 28.5 | G35: 0 | H35: 24.04
A36: 1 | B36: 1 | C36: JIT | D36: Матриці | E36: 2 | F36: 27.86 | G36: 0 | H36: 24.07
A37: 1 | B37: 1 | C37: JIT | D37: Матриці | E37: 3 | F37: 27.99 | G37: 0 | H37: 24.09
A38: 2 | B38: 1 | C38: Native AOT | D38: Матриці | E38: 0 | F38: 25.6 | G38: 0 | H38: 11.83
A39: 2 | B39: 1 | C39: Native AOT | D39: Матриці | E39: 1 | F39: 25.79 | G39: 0 | H39: 11.1
A40: 2 | B40: 1 | C40: Native AOT | D40: Матриці | E40: 2 | F40: 25.3 | G40: 0 | H40: 11.11
A41: 2 | B41: 1 | C41: Native AOT | D41: Матриці | E41: 3 | F41: 25.37 | G41: 0 | H41: 11.12
A42: 3 | B42: 2 | C42: JIT | D42: Об’єкти та GC | E42: 0 | F42: 7.1 | G42: 8.39 | H42: 29.79 | I42: 2 | J42: 1 | K42: 0 | L42: 2.12
A43: 3 | B43: 2 | C43: JIT | D43: Об’єкти та GC | E43: 1 | F43: 2.19 | G43: 8.39 | H43: 31.17 | I43: 1 | J43: 0 | K43: 0 | L43: 0.81
A44: 3 | B44: 2 | C44: JIT | D44: Об’єкти та GC | E44: 2 | F44: 1.99 | G44: 8.39 | H44: 31.23 | I44: 1 | J44: 0 | K44: 0 | L44: 0.68
A45: 3 | B45: 2 | C45: JIT | D45: Об’єкти та GC | E45: 3 | F45: 2.04 | G45: 8.39 | H45: 31.25 | I45: 1 | J45: 0 | K45: 0 | L45: 0.5
...
